<?xml version="1.0" ?>
<!-- =================================================================================== -->
<!-- |    This document was autogenerated by xacro from s500_uam_arm_effort.urdf.xacro | -->
<!-- |    EDITING THIS FILE BY HAND IS NOT RECOMMENDED                                 | -->
<!-- =================================================================================== -->
<robot name="s500_uam_arm">
  <!-- Links -->
  <link name="world"/>
  <joint name="world_joint" type="fixed">
    <parent link="world"/>
    <child link="base_link"/>
    <origin rpy="0 0 0" xyz="0 0 0"/>
  </joint>
  <link name="base_link">
    <inertial>
      <origin rpy="0 0 0" xyz="0 0 0"/>
      <mass value="1.772"/>
      <inertia ixx="0.0165" ixy="0" ixz="0" iyy="0.0186" iyz="0" izz="0.0250"/>
    </inertial>
    <visual>
      <origin rpy="0 0 0" xyz="0 0 0"/>
      <geometry>
        <mesh filename="model://s500_uam/meshes/base_link.STL" scale="1 1 1"/>
      </geometry>
      <material name="DarkGrey"/>
    </visual>
    <collision>
      <origin rpy="0 0 0" xyz="0 0 0"/>
      <geometry>
        <box size="0.47 0.47 0.35"/>
      </geometry>
    </collision>
  </link>
  <link name="link_1">
    <inertial>
      <origin
        xyz="-0 -0.000196 -0.076809"
        rpy="0 0 0" />
      <mass
        value="0.095" />
      <inertia
        ixx="5.8e-05"
        ixy="0"
        ixz="0"
        iyy="5.1e-05"
        iyz="0"
        izz="1.8e-05" />
    </inertial>
    <visual>
      <origin
        xyz="0 0 0"
        rpy="0 0 0" />
      <geometry>
        <mesh
          filename="package://example-robot-data/robots/s500_description/s500_uam/meshes/link_1.STL" />
      </geometry>
      <material
        name="">
        <color
          rgba="1 1 1 1" />
      </material>
    </visual>
    <collision>
      <origin
        xyz="0 0 0"
        rpy="0 0 0" />
      <geometry>
        <mesh
          filename="package://example-robot-data/robots/s500_description/s500_uam/meshes/link_1.STL" />
      </geometry>
    </collision>
  </link>

  <joint name="joint_1" type="revolute">
    <origin
      xyz="0.0007 0 -0.07275"
      rpy="0 0 0" />
    <parent
      link="base_link" />
    <child
      link="link_1" />
    <axis xyz="0 1 0" />
    <limit effort="10" lower="-2" upper="2" velocity="20"/>
    <!-- <dynamics damping="0.1" friction="0.1"/> -->
  </joint>

  <link name="link_2">
    <inertial>
      <origin
        xyz="0.000575 0.000247 -0.072261"
        rpy="0 0 0" />
      <mass
        value="0.082" />
      <inertia
        ixx="4.3e-05"
        ixy="0"
        ixz="0"
        iyy="4.1e-05"
        iyz="0"
        izz="2.6e-05" />
    </inertial>
    <visual>
      <origin
        xyz="0 0 0"
        rpy="0 0 0" />
      <geometry>
        <mesh
          filename="package://example-robot-data/robots/s500_description/s500_uam/meshes/link_2.STL" />
      </geometry>
      <material
        name="">
        <color
          rgba="1 1 1 1" />
      </material>
    </visual>
    <collision>
      <origin
        xyz="0 0 0"
        rpy="0 0 0" />
      <geometry>
        <mesh
          filename="package://example-robot-data/robots/s500_description/s500_uam/meshes/link_2.STL" />
      </geometry>
    </collision>
  </link>

  <joint name="joint_2" type="revolute">
    <origin
      xyz="0 0 -0.09925"
      rpy="0 0 0" />
    <parent
      link="link_1" />
    <child
      link="link_2" />
    <axis xyz="0 1 0" />
    <limit effort="10" lower="-2" upper="2" velocity="20"/>
    <!-- <dynamics damping="0.1" friction="0.1"/> -->
  </joint>

  <link name="link_3">
    <inertial>
      <origin
        xyz="0.025274 0.000991 -0.041284"
        rpy="0 0 0" />
      <mass
        value="0.012" />
      <inertia
        ixx="1.0e-05"
        ixy="0"
        ixz="0"
        iyy="1.0e-05"
        iyz="0"
        izz="2.0e-06" />
    </inertial>
    <visual>
      <origin
        xyz="0 0 0"
        rpy="0 0 0" />
      <geometry>
        <mesh
          filename="package://example-robot-data/robots/s500_description/s500_uam/meshes/link_3.STL" />
      </geometry>
      <material
        name="">
        <color
          rgba="0.92157 0.92157 0.92157 1" />
      </material>
    </visual>
    <collision>
      <origin
        xyz="0 0 0"
        rpy="0 0 0" />
      <geometry>
        <mesh
          filename="package://example-robot-data/robots/s500_description/s500_uam/meshes/link_3.STL" />
      </geometry>
    </collision>
  </link>

  <joint name="joint_3" type="fixed">
    <origin
      xyz="-0.011 0 -0.08225"
      rpy="0 0.23432 3.1416" />
    <parent
      link="link_2" />
    <child
      link="link_3" />
    <axis
      xyz="0 1 0" />
    <limit
      lower="-1.57"
      upper="0"
      effort="10"
      velocity="1" />
  </joint>

  <link name="link_4">
    <inertial>
      <origin
        xyz="0.024422 -0.000991 -0.039818"
        rpy="0 0 0" />
      <mass
        value="0.012" />
      <inertia
        ixx="1.0e-05"
        ixy="0"
        ixz="0"
        iyy="1.0e-05"
        iyz="0"
        izz="2.0e-06" />
    </inertial>
    <visual>
      <origin
        xyz="0 0 0"
        rpy="0 0 0" />
      <geometry>
        <mesh
          filename="package://example-robot-data/robots/s500_description/s500_uam/meshes/link_4.STL" />
      </geometry>
      <material
        name="">
        <color
          rgba="0.92157 0.92157 0.92157 1" />
      </material>
    </visual>
    <collision>
      <origin
        xyz="0 0 0"
        rpy="0 0 0" />
      <geometry>
        <mesh
          filename="package://example-robot-data/robots/s500_description/s500_uam/meshes/link_4.STL" />
      </geometry>
    </collision>
  </link>

  <joint name="joint_4" type="fixed">
    <origin
      xyz="0.011 0 -0.08225"
      rpy="0 0.26237 0" />
    <parent
      link="link_2" />
    <child
      link="link_4" />
    <axis
      xyz="0 1 0" />
    <limit
      lower="0"
      upper="1.57"
      effort="10"
      velocity="1" />
  </joint>

  <link name="gripper_link">
    <inertial>
      <origin xyz="0 0 0" rpy="0 0 0" />
      <mass value="0.001" />
      <inertia ixx="1e-9" ixy="0" ixz="0" iyy="1e-9" iyz="0" izz="1e-9" />
    </inertial>
    <visual>
        <origin xyz="0 0 0" rpy="0 0 0" />
        <geometry>
            <box size="0.01 0.01 0.01" /> 
        </geometry>
        <material name="">
            <color rgba="1 0 0 0.5" /> 
        </material>
    </visual>

  </link>

  <joint name="gripper_joint" type="fixed">
    <origin xyz="0 0 -0.14" rpy="0 0 0" />  
    <parent link="link_2" />
    <child link="gripper_link" />
  </joint>



  <!-- Transmissions for ros_control -->
  <transmission name="joint_1_trans">
    <type>transmission_interface/SimpleTransmission</type>
    <joint name="joint_1">
      <!-- <hardwareInterface>hardware_interface/PositionJointInterface</hardwareInterface>
      <hardwareInterface>hardware_interface/VelocityJointInterface</hardwareInterface> -->
      <hardwareInterface>hardware_interface/EffortJointInterface</hardwareInterface>
    </joint>
    <actuator name="joint_1_motor">
      <!-- <hardwareInterface>hardware_interface/PositionJointInterface</hardwareInterface>
      <hardwareInterface>hardware_interface/VelocityJointInterface</hardwareInterface>
      <hardwareInterface>hardware_interface/EffortJointInterface</hardwareInterface>
      <mechanicalReduction>1.0</mechanicalReduction> -->
    </actuator>
  </transmission>
  <transmission name="joint_2_trans">
    <type>transmission_interface/SimpleTransmission</type>
    <joint name="joint_2">
      <!-- <hardwareInterface>hardware_interface/PositionJointInterface</hardwareInterface>
      <hardwareInterface>hardware_interface/VelocityJointInterface</hardwareInterface> -->
      <hardwareInterface>hardware_interface/EffortJointInterface</hardwareInterface>
    </joint>
    <actuator name="joint_2_motor">
      <!-- <hardwareInterface>hardware_interface/PositionJointInterface</hardwareInterface>
      <hardwareInterface>hardware_interface/VelocityJointInterface</hardwareInterface>
      <hardwareInterface>hardware_interface/EffortJointInterface</hardwareInterface>
      <mechanicalReduction>1.0</mechanicalReduction> -->
    </actuator>
  </transmission>
  <transmission name="joint_3_trans">
    <type>transmission_interface/SimpleTransmission</type>
    <joint name="joint_3">
      <hardwareInterface>hardware_interface/PositionJointInterface</hardwareInterface>
      <!-- <hardwareInterface>hardware_interface/VelocityJointInterface</hardwareInterface>
      <hardwareInterface>hardware_interface/EffortJointInterface</hardwareInterface> -->
    </joint>
    <actuator name="joint_3_motor">
      <!-- <hardwareInterface>hardware_interface/PositionJointInterface</hardwareInterface>
      <hardwareInterface>hardware_interface/VelocityJointInterface</hardwareInterface>
      <hardwareInterface>hardware_interface/EffortJointInterface</hardwareInterface>
      <mechanicalReduction>1.0</mechanicalReduction> -->
    </actuator>
  </transmission>
  <transmission name="joint_4_trans">
    <type>transmission_interface/SimpleTransmission</type>
    <joint name="joint_4">
      <hardwareInterface>hardware_interface/PositionJointInterface</hardwareInterface>
      <!-- <hardwareInterface>hardware_interface/VelocityJointInterface</hardwareInterface>
      <hardwareInterface>hardware_interface/EffortJointInterface</hardwareInterface> -->
    </joint>
    <actuator name="joint_4_motor">
      <!-- <hardwareInterface>hardware_interface/PositionJointInterface</hardwareInterface>
      <hardwareInterface>hardware_interface/VelocityJointInterface</hardwareInterface>
      <hardwareInterface>hardware_interface/EffortJointInterface</hardwareInterface>
      <mechanicalReduction>1.0</mechanicalReduction> -->
    </actuator>
  </transmission>
  <gazebo>
    <plugin filename="libgazebo_ros_control.so" name="gazebo_ros_control">
      <robotNamespace>/s500_uam</robotNamespace>
      <controlPeriod>0.001</controlPeriod>
      <robotParam>/s500_uam/robot_description</robotParam>
      <legacyModeNS>true</legacyModeNS>
    </plugin>
  </gazebo>
</robot>

